[2024-03-20T17:36:20.724+0000] {taskinstance.py:1979} INFO - Dependencies all met for dep_context=non-requeueable deps ti=<TaskInstance: welcome_dag.print_random_quote manual__2024-03-20T17:36:10.513252+00:00 [queued]>
[2024-03-20T17:36:20.818+0000] {taskinstance.py:1979} INFO - Dependencies all met for dep_context=requeueable deps ti=<TaskInstance: welcome_dag.print_random_quote manual__2024-03-20T17:36:10.513252+00:00 [queued]>
[2024-03-20T17:36:20.820+0000] {taskinstance.py:2193} INFO - Starting attempt 1 of 1
[2024-03-20T17:36:20.949+0000] {taskinstance.py:2217} INFO - Executing <Task(PythonOperator): print_random_quote> on 2024-03-20 17:36:10.513252+00:00
[2024-03-20T17:36:20.954+0000] {standard_task_runner.py:60} INFO - Started process 106 to run task
[2024-03-20T17:36:20.958+0000] {standard_task_runner.py:87} INFO - Running: ['airflow', 'tasks', 'run', 'welcome_dag', 'print_random_quote', 'manual__2024-03-20T17:36:10.513252+00:00', '--job-id', '4', '--raw', '--subdir', 'DAGS_FOLDER/welcome-dag.py', '--cfg-path', '/tmp/tmphnfb317w']
[2024-03-20T17:36:20.961+0000] {standard_task_runner.py:88} INFO - Job 4: Subtask print_random_quote
[2024-03-20T17:36:21.178+0000] {task_command.py:423} INFO - Running <TaskInstance: welcome_dag.print_random_quote manual__2024-03-20T17:36:10.513252+00:00 [running]> on host 9fbe6db98bd8
[2024-03-20T17:36:21.773+0000] {taskinstance.py:2513} INFO - Exporting env vars: AIRFLOW_CTX_DAG_OWNER='airflow' AIRFLOW_CTX_DAG_ID='welcome_dag' AIRFLOW_CTX_TASK_ID='print_random_quote' AIRFLOW_CTX_EXECUTION_DATE='2024-03-20T17:36:10.513252+00:00' AIRFLOW_CTX_TRY_NUMBER='1' AIRFLOW_CTX_DAG_RUN_ID='manual__2024-03-20T17:36:10.513252+00:00'
[2024-03-20T17:36:21.776+0000] {taskinstance.py:2731} ERROR - Task failed with exception
Traceback (most recent call last):
  File "/home/airflow/.local/lib/python3.8/site-packages/airflow/models/taskinstance.py", line 444, in _execute_task
    result = _execute_callable(context=context, **execute_callable_kwargs)
  File "/home/airflow/.local/lib/python3.8/site-packages/airflow/models/taskinstance.py", line 414, in _execute_callable
    return execute_callable(context=context, **execute_callable_kwargs)
  File "/home/airflow/.local/lib/python3.8/site-packages/airflow/operators/python.py", line 200, in execute
    return_value = self.execute_callable()
  File "/home/airflow/.local/lib/python3.8/site-packages/airflow/operators/python.py", line 217, in execute_callable
    return self.python_callable(*self.op_args, **self.op_kwargs)
  File "/opt/airflow/dags/welcome-dag.py", line 15, in print_random_quote
    response = request.get('https://api.quoteable.io/random')
NameError: name 'request' is not defined
[2024-03-20T17:36:21.793+0000] {taskinstance.py:1149} INFO - Marking task as FAILED. dag_id=welcome_dag, task_id=print_random_quote, execution_date=20240320T173610, start_date=20240320T173620, end_date=20240320T173621
[2024-03-20T17:36:21.944+0000] {standard_task_runner.py:107} ERROR - Failed to execute job 4 for task print_random_quote (name 'request' is not defined; 106)
[2024-03-20T17:36:21.975+0000] {local_task_job_runner.py:234} INFO - Task exited with return code 1
[2024-03-20T17:36:22.020+0000] {taskinstance.py:3312} INFO - 0 downstream tasks scheduled from follow-on schedule check
